<?xml version="1.0"?>
<robot xmlns:xacro="http://www.ros.org/wiki/xacro" name="my_robot">
<xacro:property name="width" value = "0.4"/>
<xacro:property name="length" value = "0.6"/>
<xacro:property name="height" value = "0.2"/>
<xacro:property name="wheel_radius" value = "0.1"/>
<xacro:property name="wheel_len" value = "0.05"/>
<xacro:property name = "caster" value = "0.05"/>

    <material name="orange">
        <color rgba="0.6 0.4 0 1"/>
    </material>

    <material name = "gray">
        <color rgba = "0.7 0.7 0.7 1"/>
    </material>

    <material name = "white">
        <color rgba="1 1 1 1"/>
    </material>
    
    <link name = "base_footprint"/>

    <joint name = "base_joint" type = "fixed">
        <parent link = "base_footprint"/>
        <child link = "base_link"/>
        <origin xyz = "0 0 0.1" rpy = "0 0 0" />
    </joint>

    <link name = "base_link">
        <visual>
            <geometry>
                <box size = "${length} ${width} ${height}" />
            </geometry>
            <origin xyz = "0 0 0.1" rpy = "0 0 0"/>
            <material name= "orange"/>
        </visual>
        <collision>
            <geometry>
                <box size = "${length} ${width} ${height}" />
            </geometry>
        </collision>
        <inertial>
            <mass value="5"/>
            <origin xyz="0 0 0" rpy = "0 0 0"/>
            <inertia ixx="0.083" ixy="0" ixz="0" iyy="0.11" iyz="0" izz="0.13"/>
        </inertial>
    </link>

    <link name = "left_wheel">
        <visual>
            <geometry>
                <cylinder radius = "${wheel_radius}" length = "${wheel_len}"/>
            </geometry>
            <origin xyz = "0 0 0" rpy = "1.57 0 0"/>
            <material name = "gray"/>
        </visual>
        <collision>
            <geometry>
                <cylinder radius = "${wheel_radius}" length = "${wheel_len}"/>
            </geometry>
            <origin xyz = "0 0 0" rpy = "1.57 0 0"/>
        </collision>
        <inertial>
            <mass value="0.5"/>
            <origin xyz="0 0 0" rpy = "0 0 0"/>
            <inertia ixx="0.0014" ixy="0" ixz="0" iyy="0.0014" iyz="0" izz="0.0025"/>
        </inertial>
    </link>
    <joint name = "base_left_wheel_joint" type = "continuous">
        <parent link = "base_link"/>
        <child link = "left_wheel"/>
        <origin xyz = "-${length/4} ${width/2 + wheel_len/2} 0"/>
        <axis xyz = "0 1 0"/>
    </joint>

    <link name = "right_wheel">
        <visual>
            <geometry>
                <cylinder radius = "${wheel_radius}" length = "${wheel_len}"/>
            </geometry>
            <origin xyz = "0 0 0" rpy = "1.57 0 0"/>
            <material name = "gray"/>
        </visual>
        <collision>
            <geometry>
                <cylinder radius = "${wheel_radius}" length = "${wheel_len}"/>
            </geometry>
            <origin xyz = "0 0 0" rpy = "1.57 0 0"/>
        </collision>
        <inertial>
            <mass value="0.5"/>
            <origin xyz="0 0 0" rpy = "0 0 0"/>
            <inertia ixx="0.0014" ixy="0" ixz="0" iyy="0.0014" iyz="0" izz="0.0025"/>
        </inertial>
    </link>
    <joint name = "base_right_wheel_joint" type = "continuous">
        <parent link = "base_link"/>
        <child link = "right_wheel"/>
        <origin xyz = "-${length/4} -${width/2 + wheel_len/2} 0"/>
        <axis xyz = "0 1 0"/>
    </joint>

    <link name = "caster_wheel">
        <visual>
            <geometry>
                <sphere radius = "${caster}"/>
            </geometry>
            <origin xyz = "0 0 0" rpy = "0 0 0"/>
            <material name = "white"/>
        </visual>
        <collision>
            <geometry>
                <sphere radius = "${caster}"/>
            </geometry>
            <origin xyz = "0 0 0" rpy = "0 0 0"/>
        </collision>
        <inertial>
            <mass value="0.2"/>
            <origin xyz="0 0 0" rpy = "0 0 0"/>
            <inertia ixx="0.001" ixy="0" ixz="0" iyy="0.001" iyz="0" izz="0.001"/>
        </inertial>
    </link>
    <joint name = "base_caster_wheel_joint" type = "fixed">
        <parent link = "base_link"/>
        <child link = "caster_wheel"/>
        <origin xyz = "0.2 0 -0.05"/>
    </joint>
    <gazebo>
        <plugin
            filename="gz_ros2_control-system"
            name="gz_ros2_control::GazeboRos2ControlPlugin"/>
    </gazebo>


    <ros2_control name="GazeboSystem" type="system">
        <hardware>
            <plugin>gz_ros2_control/GazeboSimSystem</plugin>
        </hardware>

        <joint name="base_left_wheel_joint">
            <command_interface name="velocity"/>
            <state_interface name="position"/>
            <state_interface name="velocity"/>
        </joint>

        <joint name="base_right_wheel_joint">
            <command_interface name="velocity"/>
            <state_interface name="position"/>
            <state_interface name="velocity"/>
        </joint>
    </ros2_control>

</robot>