<robot name="my_robot">
  <material name="orange">
    <color rgba="0.6 0.4 0 1"/>
  </material>
  <material name="gray">
    <color rgba="0.7 0.7 0.7 1"/>
  </material>
  <material name="white">
    <color rgba="1 1 1 1"/>
  </material>
  <link name="base_footprint"/>
  <joint name="base_joint" type="fixed">
    <parent link="base_footprint"/>
    <child link="base_link"/>
    <origin rpy="0 0 0" xyz="0 0 0.1"/>
  </joint>
  <link name="base_link">
    <visual>
      <geometry>
        <box size="0.6 0.4 0.2"/>
      </geometry>
      <origin rpy="0 0 0" xyz="0 0 0.1"/>
      <material name="orange"/>
    </visual>
    <collision>
      <geometry>
        <box size="0.6 0.4 0.2"/>
      </geometry>
    </collision>
    <inertial>
      <mass value="5"/>
      <origin rpy="0 0 0" xyz="0 0 0"/>
      <inertia ixx="0.083" ixy="0" ixz="0" iyy="0.11" iyz="0" izz="0.13"/>
    </inertial>
  </link>
  <link name="left_wheel">
    <visual>
      <geometry>
        <cylinder length="0.05" radius="0.1"/>
      </geometry>
      <origin rpy="1.57 0 0" xyz="0 0 0"/>
      <material name="gray"/>
    </visual>
    <collision>
      <geometry>
        <cylinder length="0.05" radius="0.1"/>
      </geometry>
      <origin rpy="1.57 0 0" xyz="0 0 0"/>
    </collision>
    <inertial>
      <mass value="0.5"/>
      <origin rpy="0 0 0" xyz="0 0 0"/>
      <inertia ixx="0.0014" ixy="0" ixz="0" iyy="0.0014" iyz="0" izz="0.0025"/>
    </inertial>
  </link>
  <joint name="base_left_wheel_joint" type="continuous">
    <parent link="base_link"/>
    <child link="left_wheel"/>
    <origin xyz="-0.15 0.225 0"/>
    <axis xyz="0 1 0"/>
  </joint>
  <link name="right_wheel">
    <visual>
      <geometry>
        <cylinder length="0.05" radius="0.1"/>
      </geometry>
      <origin rpy="1.57 0 0" xyz="0 0 0"/>
      <material name="gray"/>
    </visual>
    <collision>
      <geometry>
        <cylinder length="0.05" radius="0.1"/>
      </geometry>
      <origin rpy="1.57 0 0" xyz="0 0 0"/>
    </collision>
    <inertial>
      <mass value="0.5"/>
      <origin rpy="0 0 0" xyz="0 0 0"/>
      <inertia ixx="0.0014" ixy="0" ixz="0" iyy="0.0014" iyz="0" izz="0.0025"/>
    </inertial>
  </link>
  <joint name="base_right_wheel_joint" type="continuous">
    <parent link="base_link"/>
    <child link="right_wheel"/>
    <origin xyz="-0.15 -0.225 0"/>
    <axis xyz="0 1 0"/>
  </joint>
  <link name="caster_wheel">
    <visual>
      <geometry>
        <sphere radius="0.05"/>
      </geometry>
      <origin rpy="0 0 0" xyz="0 0 0"/>
      <material name="white"/>
    </visual>
    <collision>
      <geometry>
        <sphere radius="0.05"/>
      </geometry>
      <origin rpy="0 0 0" xyz="0 0 0"/>
    </collision>
    <inertial>
      <mass value="0.2"/>
      <origin rpy="0 0 0" xyz="0 0 0"/>
      <inertia ixx="0.001" ixy="0" ixz="0" iyy="0.001" iyz="0" izz="0.001"/>
    </inertial>
  </link>
  <joint name="base_caster_wheel_joint" type="fixed">
    <parent link="base_link"/>
    <child link="caster_wheel"/>
    <origin xyz="0.2 0 -0.05"/>
  </joint>
  <gazebo>
    <plugin filename="libgazebo_ros_diff_drive.so" name="diff_drive_controller">
      <ros>
        <namespace>/</namespace>
        <remapping>cmd_vel:=cmd_vel</remapping>
        <remapping>odom:=odom</remapping>
      </ros>
      <robotBaseFrame>base_link</robotBaseFrame>
      <leftJoint>base_left_wheel_joint</leftJoint>
      <rightJoint>base_right_wheel_joint</rightJoint>
      <wheelSeparation>0.45</wheelSeparation>
      <wheelDiameter>0.2</wheelDiameter>
      <torque>5.0</torque>
      <publishWheelTF>true</publishWheelTF>
    </plugin>
  </gazebo>
</robot>
